<?xml version="1.0"?>
<robot xmlns:xacro="http://www.ros.org/wiki/xacro" name="humanoid_robot">

  <!-- Constants -->
  <xacro:property name="M_PI" value="3.1415926535897931" />

  <!-- Base link -->
  <link name="base_link">
    <visual>
      <geometry>
        <box size="0.3 0.2 0.5"/>
      </geometry>
      <material name="light_grey">
        <color rgba="0.7 0.7 0.7 1.0"/>
      </material>
    </visual>
    <collision>
      <geometry>
        <box size="0.3 0.2 0.5"/>
      </geometry>
    </collision>
    <inertial>
      <mass value="10"/>
      <inertia ixx="1" ixy="0" ixz="0" iyy="1" iyz="0" izz="1"/>
    </inertial>
  </link>

  <!-- Head -->
  <joint name="head_joint" type="fixed">
    <parent link="base_link"/>
    <child link="head"/>
    <origin xyz="0 0 0.3" rpy="0 0 0"/>
  </joint>

  <link name="head">
    <visual>
      <geometry>
        <sphere radius="0.1"/>
      </geometry>
      <material name="white">
        <color rgba="1 1 1 1"/>
      </material>
    </visual>
    <collision>
      <geometry>
        <sphere radius="0.1"/>
      </geometry>
    </collision>
    <inertial>
      <mass value="1"/>
      <inertia ixx="0.01" ixy="0" ixz="0" iyy="0.01" iyz="0" izz="0.01"/>
    </inertial>
  </link>

  <!-- Camera for perception -->
  <joint name="camera_joint" type="fixed">
    <parent link="head"/>
    <child link="camera_link"/>
    <origin xyz="0.05 0 0" rpy="0 0 0"/>
  </joint>

  <link name="camera_link">
    <inertial>
      <mass value="0.1"/>
      <inertia ixx="0.001" ixy="0" ixz="0" iyy="0.001" iyz="0" izz="0.001"/>
    </inertial>
  </link>

  <!-- Torso -->
  <joint name="torso_joint" type="fixed">
    <parent link="base_link"/>
    <child link="torso"/>
    <origin xyz="0 0 -0.25" rpy="0 0 0"/>
  </joint>

  <link name="torso">
    <visual>
      <geometry>
        <box size="0.25 0.15 0.4"/>
      </geometry>
      <material name="light_blue">
        <color rgba="0.5 0.5 1.0 1.0"/>
      </material>
    </visual>
    <collision>
      <geometry>
        <box size="0.25 0.15 0.4"/>
      </geometry>
    </collision>
    <inertial>
      <mass value="5"/>
      <inertia ixx="0.2" ixy="0" ixz="0" iyy="0.2" iyz="0" izz="0.2"/>
    </inertial>
  </link>

  <!-- Left Arm -->
  <joint name="left_shoulder_joint" type="revolute">
    <parent link="torso"/>
    <child link="left_upper_arm"/>
    <origin xyz="0.15 0.1 0" rpy="0 0 0"/>
    <axis xyz="0 1 0"/>
    <limit lower="${-M_PI/2}" upper="${M_PI/2}" effort="100" velocity="1"/>
  </joint>

  <link name="left_upper_arm">
    <visual>
      <geometry>
        <cylinder length="0.3" radius="0.05"/>
      </geometry>
      <origin xyz="0 0 -0.15" rpy="0 0 0"/>
      <material name="light_grey">
        <color rgba="0.7 0.7 0.7 1.0"/>
      </material>
    </visual>
    <collision>
      <geometry>
        <cylinder length="0.3" radius="0.05"/>
      </geometry>
      <origin xyz="0 0 -0.15" rpy="0 0 0"/>
    </collision>
    <inertial>
      <mass value="1"/>
      <inertia ixx="0.01" ixy="0" ixz="0" iyy="0.01" iyz="0" izz="0.01"/>
    </inertial>
  </link>

  <joint name="left_elbow_joint" type="revolute">
    <parent link="left_upper_arm"/>
    <child link="left_lower_arm"/>
    <origin xyz="0 0 -0.3" rpy="0 0 0"/>
    <axis xyz="0 1 0"/>
    <limit lower="${-M_PI/2}" upper="${M_PI/2}" effort="100" velocity="1"/>
  </joint>

  <link name="left_lower_arm">
    <visual>
      <geometry>
        <cylinder length="0.25" radius="0.04"/>
      </geometry>
      <origin xyz="0 0 -0.125" rpy="0 0 0"/>
      <material name="light_grey">
        <color rgba="0.7 0.7 0.7 1.0"/>
      </material>
    </visual>
    <collision>
      <geometry>
        <cylinder length="0.25" radius="0.04"/>
      </geometry>
      <origin xyz="0 0 -0.125" rpy="0 0 0"/>
    </collision>
    <inertial>
      <mass value="0.5"/>
      <inertia ixx="0.005" ixy="0" ixz="0" iyy="0.005" iyz="0" izz="0.005"/>
    </inertial>
  </link>

  <!-- Right Arm -->
  <joint name="right_shoulder_joint" type="revolute">
    <parent link="torso"/>
    <child link="right_upper_arm"/>
    <origin xyz="0.15 -0.1 0" rpy="0 0 0"/>
    <axis xyz="0 1 0"/>
    <limit lower="${-M_PI/2}" upper="${M_PI/2}" effort="100" velocity="1"/>
  </joint>

  <link name="right_upper_arm">
    <visual>
      <geometry>
        <cylinder length="0.3" radius="0.05"/>
      </geometry>
      <origin xyz="0 0 -0.15" rpy="0 0 0"/>
      <material name="light_grey">
        <color rgba="0.7 0.7 0.7 1.0"/>
      </material>
    </visual>
    <collision>
      <geometry>
        <cylinder length="0.3" radius="0.05"/>
      </geometry>
      <origin xyz="0 0 -0.15" rpy="0 0 0"/>
    </collision>
    <inertial>
      <mass value="1"/>
      <inertia ixx="0.01" ixy="0" ixz="0" iyy="0.01" iyz="0" izz="0.01"/>
    </inertial>
  </link>

  <joint name="right_elbow_joint" type="revolute">
    <parent link="right_upper_arm"/>
    <child link="right_lower_arm"/>
    <origin xyz="0 0 -0.3" rpy="0 0 0"/>
    <axis xyz="0 1 0"/>
    <limit lower="${-M_PI/2}" upper="${M_PI/2}" effort="100" velocity="1"/>
  </joint>

  <link name="right_lower_arm">
    <visual>
      <geometry>
        <cylinder length="0.25" radius="0.04"/>
      </geometry>
      <origin xyz="0 0 -0.125" rpy="0 0 0"/>
      <material name="light_grey">
        <color rgba="0.7 0.7 0.7 1.0"/>
      </material>
    </visual>
    <collision>
      <geometry>
        <cylinder length="0.25" radius="0.04"/>
      </geometry>
      <origin xyz="0 0 -0.125" rpy="0 0 0"/>
    </collision>
    <inertial>
      <mass value="0.5"/>
      <inertia ixx="0.005" ixy="0" ixz="0" iyy="0.005" iyz="0" izz="0.005"/>
    </inertial>
  </link>

  <!-- Left Leg -->
  <joint name="left_hip_joint" type="revolute">
    <parent link="base_link"/>
    <child link="left_upper_leg"/>
    <origin xyz="-0.1 0.05 -0.25" rpy="0 0 0"/>
    <axis xyz="0 1 0"/>
    <limit lower="${-M_PI/2}" upper="${M_PI/2}" effort="100" velocity="1"/>
  </joint>

  <link name="left_upper_leg">
    <visual>
      <geometry>
        <cylinder length="0.4" radius="0.06"/>
      </geometry>
      <origin xyz="0 0 -0.2" rpy="0 0 0"/>
      <material name="light_grey">
        <color rgba="0.7 0.7 0.7 1.0"/>
      </material>
    </visual>
    <collision>
      <geometry>
        <cylinder length="0.4" radius="0.06"/>
      </geometry>
      <origin xyz="0 0 -0.2" rpy="0 0 0"/>
    </collision>
    <inertial>
      <mass value="2"/>
      <inertia ixx="0.04" ixy="0" ixz="0" iyy="0.04" iyz="0" izz="0.04"/>
    </inertial>
  </link>

  <joint name="left_knee_joint" type="revolute">
    <parent link="left_upper_leg"/>
    <child link="left_lower_leg"/>
    <origin xyz="0 0 -0.4" rpy="0 0 0"/>
    <axis xyz="0 1 0"/>
    <limit lower="${-M_PI/2}" upper="${M_PI/2}" effort="100" velocity="1"/>
  </joint>

  <link name="left_lower_leg">
    <visual>
      <geometry>
        <cylinder length="0.4" radius="0.05"/>
      </geometry>
      <origin xyz="0 0 -0.2" rpy="0 0 0"/>
      <material name="light_grey">
        <color rgba="0.7 0.7 0.7 1.0"/>
      </material>
    </visual>
    <collision>
      <geometry>
        <cylinder length="0.4" radius="0.05"/>
      </geometry>
      <origin xyz="0 0 -0.2" rpy="0 0 0"/>
    </collision>
    <inertial>
      <mass value="1.5"/>
      <inertia ixx="0.03" ixy="0" ixz="0" iyy="0.03" iyz="0" izz="0.03"/>
    </inertial>
  </link>

  <!-- Right Leg -->
  <joint name="right_hip_joint" type="revolute">
    <parent link="base_link"/>
    <child link="right_upper_leg"/>
    <origin xyz="-0.1 -0.05 -0.25" rpy="0 0 0"/>
    <axis xyz="0 1 0"/>
    <limit lower="${-M_PI/2}" upper="${M_PI/2}" effort="100" velocity="1"/>
  </joint>

  <link name="right_upper_leg">
    <visual>
      <geometry>
        <cylinder length="0.4" radius="0.06"/>
      </geometry>
      <origin xyz="0 0 -0.2" rpy="0 0 0"/>
      <material name="light_grey">
        <color rgba="0.7 0.7 0.7 1.0"/>
      </material>
    </visual>
    <collision>
      <geometry>
        <cylinder length="0.4" radius="0.06"/>
      </geometry>
      <origin xyz="0 0 -0.2" rpy="0 0 0"/>
    </collision>
    <inertial>
      <mass value="2"/>
      <inertia ixx="0.04" ixy="0" ixz="0" iyy="0.04" iyz="0" izz="0.04"/>
    </inertial>
  </link>

  <joint name="right_knee_joint" type="revolute">
    <parent link="right_upper_leg"/>
    <child link="right_lower_leg"/>
    <origin xyz="0 0 -0.4" rpy="0 0 0"/>
    <axis xyz="0 1 0"/>
    <limit lower="${-M_PI/2}" upper="${M_PI/2}" effort="100" velocity="1"/>
  </joint>

  <link name="right_lower_leg">
    <visual>
      <geometry>
        <cylinder length="0.4" radius="0.05"/>
      </geometry>
      <origin xyz="0 0 -0.2" rpy="0 0 0"/>
      <material name="light_grey">
        <color rgba="0.7 0.7 0.7 1.0"/>
      </material>
    </visual>
    <collision>
      <geometry>
        <cylinder length="0.4" radius="0.05"/>
      </geometry>
      <origin xyz="0 0 -0.2" rpy="0 0 0"/>
    </collision>
    <inertial>
      <mass value="1.5"/>
      <inertia ixx="0.03" ixy="0" ixz="0" iyy="0.03" iyz="0" izz="0.03"/>
    </inertial>
  </link>

  <!-- Gazebo plugin for the robot -->
  <gazebo>
    <plugin name="gazebo_ros_control" filename="libgazebo_ros_control.so">
      <robotNamespace>/humanoid</robotNamespace>
    </plugin>
  </gazebo>

  <!-- Gazebo materials -->
  <gazebo reference="base_link">
    <material>Gazebo/Grey</material>
  </gazebo>

  <gazebo reference="head">
    <material>Gazebo/White</material>
  </gazebo>

  <gazebo reference="torso">
    <material>Gazebo/Blue</material>
  </gazebo>

  <gazebo reference="left_upper_arm">
    <material>Gazebo/Grey</material>
  </gazebo>

  <gazebo reference="left_lower_arm">
    <material>Gazebo/Grey</material>
  </gazebo>

  <gazebo reference="right_upper_arm">
    <material>Gazebo/Grey</material>
  </gazebo>

  <gazebo reference="right_lower_arm">
    <material>Gazebo/Grey</material>
  </gazebo>

  <gazebo reference="left_upper_leg">
    <material>Gazebo/Grey</material>
  </gazebo>

  <gazebo reference="left_lower_leg">
    <material>Gazebo/Grey</material>
  </gazebo>

  <gazebo reference="right_upper_leg">
    <material>Gazebo/Grey</material>
  </gazebo>

  <gazebo reference="right_lower_leg">
    <material>Gazebo/Grey</material>
  </gazebo>

</robot>