<?xml version="1.0"?>
<robot xmlns:xacro="http://www.ros.org/wiki/xacro" name="humanoid">

  <xacro:property name="M_PI" value="3.1415926535897931" />

  <!-- Base Link -->
  <link name="base_link">
    <visual>
      <geometry>
        <box size="0.3 0.2 0.4"/>
      </geometry>
      <material name="light_grey">
        <color rgba="0.7 0.7 0.7 1.0"/>
      </material>
    </visual>
    <collision>
      <geometry>
        <box size="0.3 0.2 0.4"/>
      </geometry>
    </collision>
    <inertial>
      <mass value="10.0" />
      <origin xyz="0 0 0" />
      <inertia ixx="0.1" ixy="0.0" ixz="0.0" iyy="0.1" iyz="0.0" izz="0.1" />
    </inertial>
  </link>

  <!-- Head -->
  <link name="head_link">
    <visual>
      <geometry>
        <sphere radius="0.1"/>
      </geometry>
      <material name="light_grey">
        <color rgba="0.7 0.7 0.7 1.0"/>
      </material>
    </visual>
    <collision>
      <geometry>
        <sphere radius="0.1"/>
      </geometry>
    </collision>
    <inertial>
      <mass value="1.0" />
      <origin xyz="0 0 0" />
      <inertia ixx="0.001" ixy="0.0" ixz="0.0" iyy="0.001" iyz="0.0" izz="0.001" />
    </inertial>
  </link>

  <joint name="head_joint" type="fixed">
    <parent link="base_link"/>
    <child link="head_link"/>
    <origin xyz="0 0 0.3" rpy="0 0 0"/>
  </joint>

  <!-- Camera -->
  <link name="camera_link">
    <visual>
      <geometry>
        <box size="0.05 0.1 0.04"/>
      </geometry>
    </visual>
    <collision>
      <geometry>
        <box size="0.05 0.1 0.04"/>
      </geometry>
    </collision>
    <inertial>
      <mass value="0.1" />
      <origin xyz="0 0 0" />
      <inertia ixx="0.001" ixy="0.0" ixz="0.0" iyy="0.001" iyz="0.0" izz="0.001" />
    </inertial>
  </link>

  <joint name="camera_joint" type="fixed">
    <parent link="head_link"/>
    <child link="camera_link"/>
    <origin xyz="0.05 0 0" rpy="0 0 0"/>
  </joint>

  <!-- Left Arm -->
  <link name="left_shoulder_link">
    <visual>
      <geometry>
        <cylinder length="0.15" radius="0.05"/>
      </geometry>
      <material name="light_grey">
        <color rgba="0.7 0.7 0.7 1.0"/>
      </material>
    </visual>
    <collision>
      <geometry>
        <cylinder length="0.15" radius="0.05"/>
      </geometry>
    </collision>
    <inertial>
      <mass value="1.0" />
      <origin xyz="0 0 0" />
      <inertia ixx="0.002" ixy="0.0" ixz="0.0" iyy="0.002" iyz="0.0" izz="0.0005" />
    </inertial>
  </link>

  <joint name="left_shoulder_joint" type="revolute">
    <parent link="base_link"/>
    <child link="left_shoulder_link"/>
    <origin xyz="0.15 0.1 0" rpy="0 0 0"/>
    <axis xyz="0 1 0"/>
    <limit lower="${-M_PI/2}" upper="${M_PI/2}" effort="100" velocity="3.0"/>
  </joint>

  <link name="left_elbow_link">
    <visual>
      <geometry>
        <cylinder length="0.2" radius="0.04"/>
      </geometry>
      <material name="light_grey">
        <color rgba="0.7 0.7 0.7 1.0"/>
      </material>
    </visual>
    <collision>
      <geometry>
        <cylinder length="0.2" radius="0.04"/>
      </geometry>
    </collision>
    <inertial>
      <mass value="0.8" />
      <origin xyz="0 0 0" />
      <inertia ixx="0.0015" ixy="0.0" ixz="0.0" iyy="0.0015" iyz="0.0" izz="0.0003" />
    </inertial>
  </link>

  <joint name="left_elbow_joint" type="revolute">
    <parent link="left_shoulder_link"/>
    <child link="left_elbow_link"/>
    <origin xyz="0 0 -0.15" rpy="0 0 0"/>
    <axis xyz="1 0 0"/>
    <limit lower="${-M_PI/2}" upper="${M_PI/2}" effort="100" velocity="3.0"/>
  </joint>

  <!-- Right Arm -->
  <link name="right_shoulder_link">
    <visual>
      <geometry>
        <cylinder length="0.15" radius="0.05"/>
      </geometry>
      <material name="light_grey">
        <color rgba="0.7 0.7 0.7 1.0"/>
      </material>
    </visual>
    <collision>
      <geometry>
        <cylinder length="0.15" radius="0.05"/>
      </geometry>
    </collision>
    <inertial>
      <mass value="1.0" />
      <origin xyz="0 0 0" />
      <inertia ixx="0.002" ixy="0.0" ixz="0.0" iyy="0.002" iyz="0.0" izz="0.0005" />
    </inertial>
  </link>

  <joint name="right_shoulder_joint" type="revolute">
    <parent link="base_link"/>
    <child link="right_shoulder_link"/>
    <origin xyz="0.15 -0.1 0" rpy="0 0 0"/>
    <axis xyz="0 1 0"/>
    <limit lower="${-M_PI/2}" upper="${M_PI/2}" effort="100" velocity="3.0"/>
  </joint>

  <link name="right_elbow_link">
    <visual>
      <geometry>
        <cylinder length="0.2" radius="0.04"/>
      </geometry>
      <material name="light_grey">
        <color rgba="0.7 0.7 0.7 1.0"/>
      </material>
    </visual>
    <collision>
      <geometry>
        <cylinder length="0.2" radius="0.04"/>
      </geometry>
    </collision>
    <inertial>
      <mass value="0.8" />
      <origin xyz="0 0 0" />
      <inertia ixx="0.0015" ixy="0.0" ixz="0.0" iyy="0.0015" iyz="0.0" izz="0.0003" />
    </inertial>
  </link>

  <joint name="right_elbow_joint" type="revolute">
    <parent link="right_shoulder_link"/>
    <child link="right_elbow_link"/>
    <origin xyz="0 0 -0.15" rpy="0 0 0"/>
    <axis xyz="1 0 0"/>
    <limit lower="${-M_PI/2}" upper="${M_PI/2}" effort="100" velocity="3.0"/>
  </joint>

  <!-- Left Leg -->
  <link name="left_hip_link">
    <visual>
      <geometry>
        <cylinder length="0.15" radius="0.06"/>
      </geometry>
      <material name="light_grey">
        <color rgba="0.7 0.7 0.7 1.0"/>
      </material>
    </visual>
    <collision>
      <geometry>
        <cylinder length="0.15" radius="0.06"/>
      </geometry>
    </collision>
    <inertial>
      <mass value="1.5" />
      <origin xyz="0 0 0" />
      <inertia ixx="0.003" ixy="0.0" ixz="0.0" iyy="0.003" iyz="0.0" izz="0.0008" />
    </inertial>
  </link>

  <joint name="left_hip_joint" type="revolute">
    <parent link="base_link"/>
    <child link="left_hip_link"/>
    <origin xyz="-0.1 0.1 -0.2" rpy="0 0 0"/>
    <axis xyz="0 1 0"/>
    <limit lower="${-M_PI/2}" upper="${M_PI/2}" effort="100" velocity="3.0"/>
  </joint>

  <link name="left_knee_link">
    <visual>
      <geometry>
        <cylinder length="0.25" radius="0.05"/>
      </geometry>
      <material name="light_grey">
        <color rgba="0.7 0.7 0.7 1.0"/>
      </material>
    </visual>
    <collision>
      <geometry>
        <cylinder length="0.25" radius="0.05"/>
      </geometry>
    </collision>
    <inertial>
      <mass value="1.2" />
      <origin xyz="0 0 0" />
      <inertia ixx="0.003" ixy="0.0" ixz="0.0" iyy="0.003" iyz="0.0" izz="0.0005" />
    </inertial>
  </link>

  <joint name="left_knee_joint" type="revolute">
    <parent link="left_hip_link"/>
    <child link="left_knee_link"/>
    <origin xyz="0 0 -0.15" rpy="0 0 0"/>
    <axis xyz="1 0 0"/>
    <limit lower="${0}" upper="${M_PI/2}" effort="100" velocity="3.0"/>
  </joint>

  <!-- Right Leg -->
  <link name="right_hip_link">
    <visual>
      <geometry>
        <cylinder length="0.15" radius="0.06"/>
      </geometry>
      <material name="light_grey">
        <color rgba="0.7 0.7 0.7 1.0"/>
      </material>
    </visual>
    <collision>
      <geometry>
        <cylinder length="0.15" radius="0.06"/>
      </geometry>
    </collision>
    <inertial>
      <mass value="1.5" />
      <origin xyz="0 0 0" />
      <inertia ixx="0.003" ixy="0.0" ixz="0.0" iyy="0.003" iyz="0.0" izz="0.0008" />
    </inertial>
  </link>

  <joint name="right_hip_joint" type="revolute">
    <parent link="base_link"/>
    <child link="right_hip_link"/>
    <origin xyz="-0.1 -0.1 -0.2" rpy="0 0 0"/>
    <axis xyz="0 1 0"/>
    <limit lower="${-M_PI/2}" upper="${M_PI/2}" effort="100" velocity="3.0"/>
  </joint>

  <link name="right_knee_link">
    <visual>
      <geometry>
        <cylinder length="0.25" radius="0.05"/>
      </geometry>
      <material name="light_grey">
        <color rgba="0.7 0.7 0.7 1.0"/>
      </material>
    </visual>
    <collision>
      <geometry>
        <cylinder length="0.25" radius="0.05"/>
      </geometry>
    </collision>
    <inertial>
      <mass value="1.2" />
      <origin xyz="0 0 0" />
      <inertia ixx="0.003" ixy="0.0" ixz="0.0" iyy="0.003" iyz="0.0" izz="0.0005" />
    </inertial>
  </link>

  <joint name="right_knee_joint" type="revolute">
    <parent link="right_hip_link"/>
    <child link="right_knee_link"/>
    <origin xyz="0 0 -0.15" rpy="0 0 0"/>
    <axis xyz="1 0 0"/>
    <limit lower="${0}" upper="${M_PI/2}" effort="100" velocity="3.0"/>
  </joint>

  <!-- Gazebo plugin for ros_control -->
  <gazebo>
    <plugin name="gazebo_ros_control" filename="libgazebo_ros_control.so">
      <parameters>$(find ros2_control)/ros2_controllers_config.yaml</parameters>
    </plugin>
  </gazebo>

  <!-- Gazebo materials -->
  <gazebo reference="base_link">
    <material>Gazebo/Grey</material>
  </gazebo>

  <gazebo reference="head_link">
    <material>Gazebo/Grey</material>
  </gazebo>

  <gazebo reference="left_shoulder_link">
    <material>Gazebo/Grey</material>
  </gazebo>

  <gazebo reference="left_elbow_link">
    <material>Gazebo/Grey</material>
  </gazebo>

  <gazebo reference="right_shoulder_link">
    <material>Gazebo/Grey</material>
  </gazebo>

  <gazebo reference="right_elbow_link">
    <material>Gazebo/Grey</material>
  </gazebo>

  <gazebo reference="left_hip_link">
    <material>Gazebo/Grey</material>
  </gazebo>

  <gazebo reference="left_knee_link">
    <material>Gazebo/Grey</material>
  </gazebo>

  <gazebo reference="right_hip_link">
    <material>Gazebo/Grey</material>
  </gazebo>

  <gazebo reference="right_knee_link">
    <material>Gazebo/Grey</material>
  </gazebo>

  <!-- Camera plugin -->
  <gazebo reference="camera_link">
    <sensor type="camera" name="camera_sensor">
      <update_rate>30</update_rate>
      <camera name="head_camera">
        <horizontal_fov>1.047</horizontal_fov>
        <image>
          <width>640</width>
          <height>480</height>
          <format>R8G8B8</format>
        </image>
        <clip>
          <near>0.1</near>
          <far>100</far>
        </clip>
      </camera>
      <plugin name="camera_controller" filename="libgazebo_ros_camera.so">
        <frame_name>camera_link</frame_name>
      </plugin>
    </sensor>
  </gazebo>

</robot>